{
  throw new AssertionError("unexpected call");
}
