{
  try {
    delegate.testRuntimeExceptionInValidatorCreationIsWrapped();
    fail("Expected a " + ValidationException.class);
  }
 catch (  ValidationException expected) {
    Throwable cause=expected.getCause();
    assertEquals(RuntimeException.class,cause.getClass());
    assertEquals("Runtime exception in validator creation",cause.getMessage());
  }
}
