{
  assertEquals(5,5);
  boolean exWasThrown=false;
  try {
    assertEquals(5,4);
  }
 catch (  Throwable ex) {
    exWasThrown=true;
    if (!(ex instanceof AssertionFailedError)) {
      fail("Unexpected type of exception during assertEquals(int,int) testing");
    }
  }
  if (!exWasThrown) {
    fail("No exception was thrown during assertEquals(int,int) testing");
  }
}
